<?xml version="1.0" ?>
<robot name="dummy_bot">
  


  <material name="grey">
                <color rgba="0.5 0.5 0.5 1"/>
  </material>

  <material name="white">
                <color rgba="1 1 1 1"/>
  </material>
  <gazebo>
  <plugin
    filename="libignition-gazebo-diff-drive-system.so"
    name="ignition::gazebo::systems::DiffDrive">
    <left_joint>left_wheel_joint</left_joint>
    <right_joint>right_wheel_joint</right_joint>
    <wheel_separation>0.8</wheel_separation>
    <wheel_radius>0.2</wheel_radius>
    <odom_publish_frequency>1</odom_publish_frequency>
    <topic>cmd_vel</topic>
</plugin>
  </gazebo>

  


  

  <link name="chassis">
    <visual>
      <geometry>
        <box size="1.5 1.0 0.5"/>
      </geometry>
      <material name="grey"/>
      
    </visual>
    <inertial>
      <mass value="1"/>
      <inertia ixx="0.1875" ixy="0.0" ixz="0.0" iyy="0.09" iyz="0.0" izz="0.27"/>
    </inertial>

    <collision>
      <geometry>
        <box size="1.5 1.0 0.5"/>
      </geometry>
    </collision>

  
  </link>

  <link name="left_wheel">
    <visual>
      <geometry>
        <cylinder length="0.3" radius="0.2"/>
      </geometry>
      
      <material name="white"/>
    </visual>
    <inertial>
      <mass value="1"/>
      <inertia ixx="0.0175" ixy="0.0" ixz="0.0" iyy="0.0175" iyz="0.0" izz="0.02"/>
    </inertial>
    <collision>
      <geometry>
        <cylinder length="0.3" radius="0.2"/>
      </geometry>
      
    </collision>

    
  </link>
  <joint name="chassis_to_left_wheel" type="revolute">
    <axis xyz="0 1 0"/>
    <limit effort="1000.0" lower="-1.79769e+308" upper="1.79769e+308" velocity="0.5"/>
    <parent link="chassis"/>
    <child link="left_wheel"/>
    <origin rpy="1.57075 0 0" xyz="0 0.65 -0.3"/>


  </joint>

  <link name="right_wheel">
    <visual>
      <geometry>
        <cylinder length="0.3" radius="0.2"/>
      </geometry>
      
      <material name="white"/>
    </visual>
    <inertial>
      <mass value="1"/>
      <inertia ixx="0.0175" ixy="0.0" ixz="0.0" iyy="0.0175" iyz="0.0" izz="0.02"/>
    </inertial>
    <collision>
      <geometry>
        <cylinder length="0.3" radius="0.2"/>
      </geometry>
      
    </collision>

    
  </link>
  <joint name="chassis_to_right_wheel" type="revolute">
    <axis xyz="0 1 0"/>
    <limit effort="1000.0" lower="-1.79769e+308" upper="1.79769e+308" velocity="0.5"/>
    <parent link="chassis"/>
    <child link="right_wheel"/>
    <origin rpy="-1.57075 0 0" xyz="0 -0.65 -0.3"/>
  </joint>

  <link name = "front_left_dummy_wheel">
    <visual>
      <geometry>
        <sphere radius = "0.2"/>
      </geometry>
      
      <material name="white"/>
    </visual>

    <inertial>
      <mass value="1"/>
      <inertia ixx="0.016" ixy="0.0" ixz="0.0" iyy="0.016" iyz="0.0" izz="0.016"/>
    </inertial>

    <collision>
      <geometry>
        <sphere radius = "0.2"/>
      </geometry>
      
    </collision>

    
  </link>

  <joint name = "chassis_to_front_left_dummy_wheel" type = "continuous">
    <parent link="chassis"/>
    <child link="front_left_dummy_wheel"/>
    <material name="white"/>
    <origin rpy="0 0 0" xyz="0.6 0.25 -0.3"/>
  </joint>



  <link name = "front_right_dummy_wheel">
    <visual>
      <geometry>
        <sphere radius = "0.2"/>
      </geometry>
      
      <material name="white"/>
    </visual>

    <inertial>
      <mass value="1"/>
      <inertia ixx="0.016" ixy="0.0" ixz="0.0" iyy="0.016" iyz="0.0" izz="0.016"/>
    </inertial>

    <collision>
      <geometry>
        <sphere radius = "0.2"/>
      </geometry>
      
    </collision>
    
  </link>

  <joint name = "chassis_to_front_right_dummy_wheel" type = "continuous">
    <parent link="chassis"/>
    <child link="front_right_dummy_wheel"/>
     <origin rpy="0 0 0" xyz="0.6 -0.25 -0.3"/>
  </joint>



  <link name = "back_right_dummy_wheel">
    <visual>
      <geometry>
        <sphere radius = "0.2"/>
      </geometry>
      
      <material name="white"/>
      
    </visual>
    

    <inertial>
      <mass value="1"/>
      <inertia ixx="0.016" ixy="0.0" ixz="0.0" iyy="0.016" iyz="0.0" izz="0.016"/>
    </inertial>

    <collision>
      <geometry>
        <sphere radius = "0.2"/>
      </geometry>
      
    </collision>
  </link>

  <joint name = "chassis_to_back_right_dummy_wheel" type = "continuous">
    <parent link="chassis"/>
    <child link="back_right_dummy_wheel"/>
    <origin rpy="0 0 0" xyz="-0.6 -0.25 -0.3"/>
  </joint>


  <link name = "back_left_dummy_wheel">
    <visual>
      <geometry>
        <sphere radius = "0.2"/>
      </geometry>
      
      <material name="white"/>
    </visual>
    <collision>
      <geometry>
        <sphere radius = "0.2"/>
      </geometry>
      
    </collision>

    <inertial>
      <mass value="1"/>
      <inertia ixx="0.016" ixy="0.0" ixz="0.0" iyy="0.016" iyz="0.0" izz="0.016"/>
    </inertial>
  </link>

  <joint name = "chassis_to_back_left_dummy_wheel" type = "continuous">
    <parent link="chassis"/>
    <child link="back_left_dummy_wheel"/>
    <origin rpy="0 0 0" xyz="-0.6 0.25 -0.3"/>
  </joint> 

    
  
</robot>

