<sdf version='1.9'>
  <model name='dummy_bot'>
    <link name='chassis'>
      <inertial>
        <pose>0 0 0 0 0 0</pose>
        <mass>1</mass>
        <inertia>
          <ixx>0.1875</ixx>
          <ixy>0</ixy>
          <ixz>0</ixz>
          <iyy>0.089999999999999997</iyy>
          <iyz>0</iyz>
          <izz>0.27000000000000002</izz>
        </inertia>
      </inertial>
      <collision name='chassis_collision'>
        <pose>0 0 0 0 0 0</pose>
        <geometry>
          <box>
            <size>1.5 1 0.5</size>
          </box>
        </geometry>
      </collision>
      <visual name='chassis_visual'>
        <pose>0 0 0 0 0 0</pose>
        <geometry>
          <box>
            <size>1.5 1 0.5</size>
          </box>
        </geometry>
        <material>
          <diffuse>0.625 0.625 0.625 1</diffuse>
          <ambient>0.625 0.625 0.625 1</ambient>
        </material>
      </visual>
    </link>
    <joint name='chassis_to_back_left_dummy_wheel' type='revolute'>
      <pose relative_to='chassis'>0 0 0 0 0 0</pose>
      <parent>chassis</parent>
      <child>back_left_dummy_wheel</child>
      <axis>
        <xyz>1 0 0</xyz>
        <limit>
          <lower>-10000000000000000</lower>
          <upper>10000000000000000</upper>
        </limit>
        <dynamics>
          <spring_reference>0</spring_reference>
          <spring_stiffness>0</spring_stiffness>
        </dynamics>
      </axis>
    </joint>
    <link name='back_left_dummy_wheel'>
      <pose relative_to='chassis_to_back_left_dummy_wheel'>0 0 0 0 0 0</pose>
      <inertial>
        <pose>0 0 0 0 0 0</pose>
        <mass>1</mass>
        <inertia>
          <ixx>0.016</ixx>
          <ixy>0</ixy>
          <ixz>0</ixz>
          <iyy>0.016</iyy>
          <iyz>0</iyz>
          <izz>0.016</izz>
        </inertia>
      </inertial>
      <collision name='back_left_dummy_wheel_collision'>
        <pose>0 0 0 0 0 0</pose>
        <geometry>
          <sphere>
            <radius>0.20000000000000001</radius>
          </sphere>
        </geometry>
      </collision>
      <visual name='back_left_dummy_wheel_visual'>
        <pose>-0.6 0.25 -0.3 0 0 0</pose>
        <geometry>
          <sphere>
            <radius>0.20000000000000001</radius>
          </sphere>
        </geometry>
        <material>
          <diffuse>1 1 1 1</diffuse>
          <ambient>1 1 1 1</ambient>
        </material>
      </visual>
    </link>
    <joint name='chassis_to_back_right_dummy_wheel' type='revolute'>
      <pose relative_to='chassis'>0 0 0 0 0 0</pose>
      <parent>chassis</parent>
      <child>back_right_dummy_wheel</child>
      <axis>
        <xyz>1 0 0</xyz>
        <limit>
          <lower>-10000000000000000</lower>
          <upper>10000000000000000</upper>
        </limit>
        <dynamics>
          <spring_reference>0</spring_reference>
          <spring_stiffness>0</spring_stiffness>
        </dynamics>
      </axis>
    </joint>
    <link name='back_right_dummy_wheel'>
      <pose relative_to='chassis_to_back_right_dummy_wheel'>0 0 0 0 0 0</pose>
      <inertial>
        <pose>0 0 0 0 0 0</pose>
        <mass>1</mass>
        <inertia>
          <ixx>0.016</ixx>
          <ixy>0</ixy>
          <ixz>0</ixz>
          <iyy>0.016</iyy>
          <iyz>0</iyz>
          <izz>0.016</izz>
        </inertia>
      </inertial>
      <collision name='back_right_dummy_wheel_collision'>
        <pose>0 0 0 0 0 0</pose>
        <geometry>
          <sphere>
            <radius>0.20000000000000001</radius>
          </sphere>
        </geometry>
      </collision>
      <visual name='back_right_dummy_wheel_visual'>
        <pose>-0.6 -0.25 -0.3 0 0 0</pose>
        <geometry>
          <sphere>
            <radius>0.20000000000000001</radius>
          </sphere>
        </geometry>
        <material>
          <diffuse>1 1 1 1</diffuse>
          <ambient>1 1 1 1</ambient>
        </material>
      </visual>
    </link>
    <joint name='chassis_to_front_left_dummy_wheel' type='revolute'>
      <pose relative_to='chassis'>0 0 0 0 0 0</pose>
      <parent>chassis</parent>
      <child>front_left_dummy_wheel</child>
      <axis>
        <xyz>1 0 0</xyz>
        <limit>
          <lower>-10000000000000000</lower>
          <upper>10000000000000000</upper>
        </limit>
        <dynamics>
          <spring_reference>0</spring_reference>
          <spring_stiffness>0</spring_stiffness>
        </dynamics>
      </axis>
    </joint>
    <link name='front_left_dummy_wheel'>
      <pose relative_to='chassis_to_front_left_dummy_wheel'>0 0 0 0 0 0</pose>
      <inertial>
        <pose>0 0 0 0 0 0</pose>
        <mass>1</mass>
        <inertia>
          <ixx>0.016</ixx>
          <ixy>0</ixy>
          <ixz>0</ixz>
          <iyy>0.016</iyy>
          <iyz>0</iyz>
          <izz>0.016</izz>
        </inertia>
      </inertial>
      <collision name='front_left_dummy_wheel_collision'>
        <pose>0 0 0 0 0 0</pose>
        <geometry>
          <sphere>
            <radius>0.20000000000000001</radius>
          </sphere>
        </geometry>
      </collision>
      <visual name='front_left_dummy_wheel_visual'>
        <pose>0.6 0.25 -0.3 0 0 0</pose>
        <geometry>
          <sphere>
            <radius>0.20000000000000001</radius>
          </sphere>
        </geometry>
        <material>
          <diffuse>1 1 1 1</diffuse>
          <ambient>1 1 1 1</ambient>
        </material>
      </visual>
    </link>
    <joint name='chassis_to_front_right_dummy_wheel' type='revolute'>
      <pose relative_to='chassis'>0 0 0 0 0 0</pose>
      <parent>chassis</parent>
      <child>front_right_dummy_wheel</child>
      <axis>
        <xyz>1 0 0</xyz>
        <limit>
          <lower>-10000000000000000</lower>
          <upper>10000000000000000</upper>
        </limit>
        <dynamics>
          <spring_reference>0</spring_reference>
          <spring_stiffness>0</spring_stiffness>
        </dynamics>
      </axis>
    </joint>
    <link name='front_right_dummy_wheel'>
      <pose relative_to='chassis_to_front_right_dummy_wheel'>0 0 0 0 0 0</pose>
      <inertial>
        <pose>0 0 0 0 0 0</pose>
        <mass>1</mass>
        <inertia>
          <ixx>0.016</ixx>
          <ixy>0</ixy>
          <ixz>0</ixz>
          <iyy>0.016</iyy>
          <iyz>0</iyz>
          <izz>0.016</izz>
        </inertia>
      </inertial>
      <collision name='front_right_dummy_wheel_collision'>
        <pose>0 0 0 0 0 0</pose>
        <geometry>
          <sphere>
            <radius>0.20000000000000001</radius>
          </sphere>
        </geometry>
      </collision>
      <visual name='front_right_dummy_wheel_visual'>
        <pose>0.6 -0.25 -0.3 0 0 0</pose>
        <geometry>
          <sphere>
            <radius>0.20000000000000001</radius>
          </sphere>
        </geometry>
        <material>
          <diffuse>1 1 1 1</diffuse>
          <ambient>1 1 1 1</ambient>
        </material>
      </visual>
    </link>
    <joint name='chassis_to_left_wheel' type='revolute'>
      <pose relative_to='chassis'>0 0 0 0 0 0</pose>
      <parent>chassis</parent>
      <child>left_wheel</child>
      <axis>
        <xyz>0 1 0</xyz>
        <limit>
          <lower>-1.7976900000000001e+308</lower>
          <upper>1.7976900000000001e+308</upper>
          <effort>1000</effort>
          <velocity>0.5</velocity>
        </limit>
        <dynamics>
          <spring_reference>0</spring_reference>
          <spring_stiffness>0</spring_stiffness>
        </dynamics>
      </axis>
    </joint>
    <link name='left_wheel'>
      <pose relative_to='chassis_to_left_wheel'>0 0 0 0 0 0</pose>
      <inertial>
        <pose>0 0 0 0 0 0</pose>
        <mass>1</mass>
        <inertia>
          <ixx>0.017500000000000002</ixx>
          <ixy>0</ixy>
          <ixz>0</ixz>
          <iyy>0.017500000000000002</iyy>
          <iyz>0</iyz>
          <izz>0.02</izz>
        </inertia>
      </inertial>
      <collision name='left_wheel_collision'>
        <pose>0 0 0 0 0 0</pose>
        <geometry>
          <cylinder>
            <length>0.29999999999999999</length>
            <radius>0.20000000000000001</radius>
          </cylinder>
        </geometry>
      </collision>
      <visual name='left_wheel_visual'>
        <pose>0 0.65 -0.3 1.57075 0 0</pose>
        <geometry>
          <cylinder>
            <length>0.29999999999999999</length>
            <radius>0.20000000000000001</radius>
          </cylinder>
        </geometry>
        <material>
          <diffuse>1 1 1 1</diffuse>
          <ambient>1 1 1 1</ambient>
        </material>
      </visual>
    </link>
    <joint name='chassis_to_right_wheel' type='revolute'>
      <pose relative_to='chassis'>0 0 0 0 0 0</pose>
      <parent>chassis</parent>
      <child>right_wheel</child>
      <axis>
        <xyz>0 1 0</xyz>
        <limit>
          <lower>-1.7976900000000001e+308</lower>
          <upper>1.7976900000000001e+308</upper>
          <effort>1000</effort>
          <velocity>0.5</velocity>
        </limit>
        <dynamics>
          <spring_reference>0</spring_reference>
          <spring_stiffness>0</spring_stiffness>
        </dynamics>
      </axis>
    </joint>
    <link name='right_wheel'>
      <pose relative_to='chassis_to_right_wheel'>0 0 0 0 0 0</pose>
      <inertial>
        <pose>0 0 0 0 0 0</pose>
        <mass>1</mass>
        <inertia>
          <ixx>0.017500000000000002</ixx>
          <ixy>0</ixy>
          <ixz>0</ixz>
          <iyy>0.017500000000000002</iyy>
          <iyz>0</iyz>
          <izz>0.02</izz>
        </inertia>
      </inertial>
      <collision name='right_wheel_collision'>
        <pose>0 0 0 0 0 0</pose>
        <geometry>
          <cylinder>
            <length>0.29999999999999999</length>
            <radius>0.20000000000000001</radius>
          </cylinder>
        </geometry>
      </collision>
      <visual name='right_wheel_visual'>
        <pose>0 -0.65 -0.3 -1.57075 0 0</pose>
        <geometry>
          <cylinder>
            <length>0.29999999999999999</length>
            <radius>0.20000000000000001</radius>
          </cylinder>
        </geometry>
        <material>
          <diffuse>1 1 1 1</diffuse>
          <ambient>1 1 1 1</ambient>
        </material>
      </visual>
    </link>
    <self_collide>true</self_collide>
    <plugin name='ignition::gazebo::systems::DiffDrive' filename='libignition-gazebo-diff-drive-system.so'>
      <left_joint>left_wheel_joint</left_joint>
      <right_joint>right_wheel_joint</right_joint>
      <wheel_separation>0.8</wheel_separation>
      <wheel_radius>0.2</wheel_radius>
      <odom_publish_frequency>1</odom_publish_frequency>
      <topic>cmd_vel</topic>
    </plugin>
  </model>
</sdf>
